Workbook

Sheet ThamSo
A1: Tham so tinh diem — SUA O CELL VANG, cac sheet khac tu tinh lai
A2: Trong so moi reply (W_REPLY) | B2: 1
A3: Trong so moi luot Ung (W_UNG) | B3: 2
A4: Do giam theo tuoi (GRAVITY, <1) | B4: 0.8
A5: Bu tuoi tinh theo gio (AGE_OFFSET_H) | B5: 6
A7: Diem goc = replies * W_REPLY + tong_Ung * W_UNG
A8: Hot score = Diem goc / (tuoi_thread_gio + AGE_OFFSET_H) ^ GRAVITY
A9: Nguon du lieu = https://voz.vn/f/diem-bao.33/ (page 1, da bo thread ghim)
A10: Thoi diem quet= 2026-10-22 15:02:59 +07
A11: Luu y: 'Ung' la reaction duy nhat cua voz (reaction id 1).
A12: Ban quyen: noi dung chi dung lam tu lieu tham khao/y tuong. Khong copy nguyen van comment cua nguoi khac len Threads.

Sheet Tong quan
A1: Hang | B1: Tieu de | C1: Link thread | D1: Link bai bao | E1: Nguon | F1: Replies | G1: Tong Ung | H1: Tuoi thread (gio) | I1: Diem goc | J1: Hot score | K1: So comment top | L1: Nguoi dang | M1: Thoi gian dang | N1: Trang da quet | O1: Trang thai | P1: Trich bai bao (post #1) | Q1: Loi
A2: =RANK(J2,$J$2:$J$21) | B2: Đề xuất người dưới 18 tuổi được hiến tạng khi có nguyện vọng và được đồng ý | C2: https://voz.vn/t/de-xuat-nguoi-duoi-18-tuoi-duoc-hien-tang-khi-co-nguyen-vong-va-duoc-dong-y.1290864/ | D2: https://tuoitre.vn/de-xuat-nguoi-duoi-18-tuoi-duoc-hien-tang-khi-co-nguyen-vong-va-duoc-dong-y-100261021092718637.htm | E2: tuoitre.vn | F2: 383 | G2: 620 | H2: 9.44 | I2: =F2*ThamSo!$B$2+G2*ThamSo!$B$3 | J2: =IFERROR(I2/POWER(H2+ThamSo!$B$5,ThamSo!$B$4),0) | K2: 20 | L2: m0use00 | M2: 2026-10-22 05:36 | N2: 20 | O2: ok | P2: ... Mở rộng phạm vi đối tượng hiến tạng, thêm hành vi bị nghiêm cấm Dự luật hoàn thiện nguyên tắc và hành vi bị nghiêm cấm khi bổ sung nguyên tắc về việc bảo đảm các yếu tố không bị cưỡng ép, bảo đảm lợi ích tốt nhất đối với trẻ em và người không có năng lực hành vi dân sự đầy đủ. Trong 8 hành vi bị nghiêm cấm, đáng chú ý là quy định cấm lợi dụng quan hệ giám hộ, chăm sóc thay thế, nuôi con nuôi để hiến, lấy mô, bộ phận cơ thể của người dưới 18 tuổi trái quy định; lấy bộ phận cơ thể ở người sống từ đủ 18 tuổi đến dưới 25 tuổi để ghép cho người không phải là thành viên gia đình. Trong các nội dung bổ sung, dự luật mở rộng nguồn hiến tạng gắn với kiểm soát chặt chẽ điều kiện người hiến. Đó là việc lấy mô, bộ phận cơ thể người sau khi chết đối với người đã được xác định là chết tuần hoàn. Người dưới 18 tuổi được đăng ký hiến và được hiến bộ phận cơ thể sau khi chết não, chết tuần hoàn với điều kiện là đã đăng ký hiến, có nguyện vọng trước khi chết và được người đại diện đồng ý. Dự thảo bổ sung các quy định cho phép người vợ được nhận tinh trùng của người chồng đã chết, chết não, chết tuần hoàn hoặc phôi của chính hai vợ chồng để sinh con; lấy tinh trùng, noãn, mô tinh hoàn, mô buồng trứng của người dưới 18 tuổi để bảo tồn khả năng sinh sản. Để ngăn chặn các hành vi trục lợi, dự thảo quy định người hiến bộ phận cơ thể khi còn sống cho người không phải thành viên trong gia đình phải từ đủ 25 tuổi trở lên; bổ sung quy định xác minh nhân thân, mối quan hệ giữa người hiến và người được ghép; bảo đảm tính độc lập trong đánh giá điều kiện hiến và tư vấn lấy, ghép, đặc biệt là đối với người dưới 18 tuổi. Đánh giá kỹ tác động, nguy cơ bị lợi dụng Trong báo cáo thẩm tra, Chủ nhiệm Ủy ban Văn hóa và Xã hội Nguyễn Đắc Vinh nêu một chính sách mới được quan tâm, đó là quy định người dưới 18 tuổi hiến mô, bộ phận cơ thể người, hiến xác. Quy định này nhằm tạo thêm cơ hội cứu chữa cho người bệnh, nhất là đối với bệnh nhi cần mô, bộ phận cơ thể có kích thước, đặc điểm giải phẫu phù hợp, đồng thời tôn trọng nguyện vọng hiến tặng của người dưới 18 tuổi và gia đình. Ủy ban ghi nhận mục đích nhân văn, nhân đạo của chính sách, song cho rằng người dưới 18 tuổi, nhất là trẻ em, là chủ thể được bảo vệ đặc biệt, do đó đề nghị tiếp tục đánh giá tác động kỹ lưỡng hệ lụy về tâm lý, đạo đức, xã hội. Đặc biệt là những nguy cơ lợi dụng quan hệ phụ thuộc để tạo áp lực, cưỡng ép lấy mô, bộ phận cơ thể, trên cơ sở đó tiếp tục nghiên cứu các quy định chặt chẽ để bảo đảm ý nghĩa tốt đẹp của chính sách. Cùng đó, dù tán thành quy định về hiến, lấy, ghép mô, bộ phận cơ thể ở người, nhưng Ủy ban đề nghị Chính phủ quy định thống nhất về nguyện vọng hiến trước khi chết là căn cứ hiến mô, bộ phận cơ thể người sau khi chết não, chết tuần hoàn. ... https://tuoitre.vn/de-xuat-nguoi-duoi-18-tuoi-duoc-hien-tang-khi-co-nguyen-vong-va-duoc-dong-y-100261021092718637.htm
A3: =RANK(J3,$J$2:$J$21) | B3: 'Kiến trúc sư' của web Xôi Lạc TV chính là bình luận viên Batman | C3: https://voz.vn/t/kien-truc-su-cua-web-xoi-lac-tv-chinh-la-binh-luan-vien-batman.1290868/ | D3: https://tienphong.vn/kien-truc-su-cua-web-xoi-lac-tv-chinh-la-binh-luan-vien-batman-post1887252.tpo | E3: tienphong.vn | F3: 212 | G3: 234 | H3: 8 | I3: =F3*ThamSo!$B$2+G3*ThamSo!$B$3 | J3: =IFERROR(I3/POWER(H3+ThamSo!$B$5,ThamSo!$B$4),0) | K3: 20 | L3: Người Thỏ | M3: 2026-10-22 07:03 | N3: 11 | O3: ok | P3: TPO - Quá trình điều tra làm rõ, bị can Nguyễn Công Định, người lập trình website Xôi Lạc TV, chuyên phát lậu các trận bóng đá, cũng chính là bình luận viên Batman của kênh này. Từ người lập trình đến bình luận viên Batman Nguyễn Công Định (biệt danh bình luận viên Batman). Viện KSND tỉnh Hưng Yên vừa ban hành cáo trạng truy tố 74 bị can trong vụ án liên quan hệ thống phát trực tiếp các trận đấu thể thao trái phép Xôi Lạc TV và các website liên quan. Trong số này, Nguyễn Công Định (biệt danh bình luận viên Batman), Phạm Nguyễn Dũng, Lương Tuấn Giang cùng 53 bị can khác bị truy tố về hai tội “Xâm phạm quyền tác giả, quyền liên quan” và “Tổ chức đánh bạc”. Ngoài ra, 17 bị can bị truy tố về tội “Tổ chức đánh bạc”; một bị can khác bị truy tố về ba tội danh, gồm “Xâm phạm quyền tác giả, quyền liên quan”, “Tổ chức đánh bạc” và “Truyền bá văn hóa phẩm đồi trụy”. Theo cáo trạng, đầu năm 2018, Nguyễn Công Định bắt đầu lập trình website Xôi Lạc TV, chuyên phát trực tiếp và bình luận các trận bóng đá được nhiều người quan tâm. Thời gian đầu, trang web hoạt động với quy mô nhỏ, lượng người theo dõi còn hạn chế. Nhận thấy tiềm năng của mô hình này, Phạm Nguyễn Dũng quyết định đầu tư để Định phát triển hệ thống website xem và bình luận bóng đá. Theo nội dung cáo trạng, Dũng chịu toàn bộ chi phí ban đầu, bao gồm đầu tư máy móc, máy chủ, cơ sở dữ liệu, trả lương nhân viên và thuê văn phòng. Định đóng góp chuyên môn, tập trung phát triển dự án; lợi nhuận dự kiến được hai bên chia đều, mỗi người hưởng 50%. Khi tham gia bình luận các trận đấu, Định sử dụng biệt danh Batman. Cái tên này dần trở nên quen thuộc với một bộ phận người xem bóng đá trực tuyến trên Xôi Lạc TV. Theo sự sắp xếp của Dũng, bộ phận phát triển hệ thống website xem và bình luận bóng đá được gọi là SBG, sau này còn được biết đến với tên dự án 90 Phút, hoạt động trong Công ty Heligate. https://tienphong.vn/kien-truc-su-cua-web-xoi-lac-tv-chinh-la-binh-luan-vien-batman-post1887252.tpo
A4: =RANK(J4,$J$2:$J$21) | B4: Tuấn Hưng: "Nếu không thích Tuấn Hưng, xin hãy phê bình Tuấn Hưng" | C4: https://voz.vn/t/tuan-hung-neu-khong-thich-tuan-hung-xin-hay-phe-binh-tuan-hung.1290986/ | D4: https://phunumoi.net.vn/tuan-hung-neu-khong-thich-tuan-hung-xin-hay-phe-binh-tuan-hung-d381885.html | E4: phunumoi.net.vn | F4: 128 | G4: 97 | H4: 1.98 | I4: =F4*ThamSo!$B$2+G4*ThamSo!$B$3 | J4: =IFERROR(I4/POWER(H4+ThamSo!$B$5,ThamSo!$B$4),0) | K4: 20 | L4: Lanh.Chanh | M4: 2026-10-22 13:04 | N4: 7 | O4: ok | P4: "Nếu không thích Tuấn Hưng, xin hãy phê bình Tuấn Hưng. Đừng vì sự không yêu mến một người mà xem nhẹ công sức của cả một cộng đoàn", Tuấn Hưng chia sẻ. Ngày 27/9, ca sĩ Tuấn Hưng tham gia biểu diễn tại một đêm nhạc thiện nguyện ở Nashville (Mỹ). Sau đó, các clip ghi lại màn trình diễn của nam ca sĩ tại đêm nhạc này được chia sẻ nhiều trên mạng xã hội với nhiều bình luận trái chiều. Mới đây, Tuấn Hưng đã lên tiếng trên trang cá nhân bày tỏ sự buồn bã khi đêm nhạc bị ví von với “tiệc thôi nôi, đám ma, đám giỗ…” trong những nội dung bình phẩm về anh. Trong bài viết, nam ca sĩ cho biết anh đã suy nghĩ rất nhiều trước khi quyết định chia sẻ cảm xúc. Tuấn Hưng nhấn mạnh, phía sau đêm nhạc là công sức của ban tổ chức, những người làm thiện nguyện và nhiều người đã dành thời gian, tiền bạc để góp sức xây dựng. Anh cho rằng bản thân chỉ là người góp tiếng hát còn những đóng góp của cộng đồng xứng đáng được nhìn nhận bằng sự tôn trọng. "Nếu không thích Tuấn Hưng, xin hãy phê bình Tuấn Hưng. Đừng vì sự không yêu mến một người mà xem nhẹ công sức của cả một cộng đoàn", nam ca sĩ viết. https://phunumoi.net.vn/tuan-hung-neu-khong-thich-tuan-hung-xin-hay-phe-binh-tuan-hung-d381885.html
A5: =RANK(J5,$J$2:$J$21) | B5: Bắt khẩn cấp nam sinh cấp 3 đấm cô giáo trên bục giảng ở Hà Nội | C5: https://voz.vn/t/bat-khan-cap-nam-sinh-cap-3-dam-co-giao-tren-buc-giang-o-ha-noi.1290619/ | D5: https://dantri.com.vn/phap-luat/bat-khan-cap-nam-sinh-cap-3-dam-co-giao-tren-buc-giang-o-ha-noi-20261021101714519.htm | E5: dantri.com.vn | F5: 306 | G5: 335 | H5: 28.17 | I5: =F5*ThamSo!$B$2+G5*ThamSo!$B$3 | J5: =IFERROR(I5/POWER(H5+ThamSo!$B$5,ThamSo!$B$4),0) | K5: 20 | L5: x-hamster | M5: 2026-10-21 10:52 | N5: 16 | O5: ok | P5: Dân trí) - Nam sinh Trường THPT Mạc Đĩnh Chi (Hà Nội) bị bắt khẩn cấp sau khi đấm cô giáo trong tiết toán. Vụ việc được lan truyền tối 20/10.​ Liên quan vụ nam sinh đấm cô giáo tại Trường THPT Mạc Đĩnh Chi, xã Nội Bài, Hà Nội, sáng 21/10, một lãnh đạo Công an TP Hà Nội xác nhận cơ quan công an đã bắt khẩn cấp nam sinh này. https://dantri.com.vn/phap-luat/bat-khan-cap-nam-sinh-cap-3-dam-co-giao-tren-buc-giang-o-ha-noi-20261021101714519.htm
A6: =RANK(J6,$J$2:$J$21) | B6: Xe taxi quyết không nhường đường ô tô đi ngược chiều, dẫn đến tai nạn đối đầu | C6: https://voz.vn/t/xe-taxi-quyet-khong-nhuong-duong-o-to-di-nguoc-chieu-dan-den-tai-nan-doi-dau.1290820/ | D6: https://thanhnien.vn/xe-taxi-quyet-khong-nhuong-duong-o-to-di-nguoc-chieu-dan-den-tai-nan-doi-dau-185261021112140398.htm | E6: thanhnien.vn | F6: 297 | G6: 158 | H6: 18.11 | I6: =F6*ThamSo!$B$2+G6*ThamSo!$B$3 | J6: =IFERROR(I6/POWER(H6+ThamSo!$B$5,ThamSo!$B$4),0) | K6: 20 | L6: ChatGPT AI | M6: 2026-10-21 20:56 | N6: 15 | O6: ok | P6: https://thanhnien.vn/xe-taxi-quyet-khong-nhuong-duong-o-to-di-nguoc-chieu-dan-den-tai-nan-doi-dau-185261021112140398.htm Không rõ do tài xế không kịp quan sát hay cố tình không nhường đường, chiếc xe taxi đã lao thẳng vào ô tô con chạy ngược chiều dẫn đến tai nạn. Tình huống giao thông nguy hiểm được xác định xảy ra vào khoảng 7 giờ 40 phút sáng 17.10.2026 trên đường dẫn vào cửa khẩu Bắc Luân 2, thuộc địa bàn phường Móng Cái 1, tỉnh Quảng Ninh. Theo hình ảnh trích xuất từ camera hành trình gắn trên ô tô cùng lưu thông, thời điểm nói trên, một xe taxi màu xanh dương đang di chuyển trên đường dẫn vào cửa khẩu Bắc Luân 2. Lúc này, phía trước bất ngờ xuất hiện một ô tô con khác màu trắng đang bất chấp luật chạy ngược chiều. Đáng nói, không rõ do tài xế xe taxi không kịp quan sát hay do cố tình không nhường đường, chiếc xe taxi sau đó đã lao thẳng vào ô tô con chạy ngược chiều dẫn đến tai nạn kiểu đối đầu. Hậu quả, hai xe bị hư hỏng nặng. Xe taxi mất lái lao ra giữa đường nhưng may mắn không gây thêm tai nạn liên hoàn. Cả 2 tài xế đều có thể bị xử phạt​ Theo quy định tại điều 12 luật Trật tự, an toàn giao thông đường bộ, người điều khiển phương tiện phải chú ý quan sát, giảm tốc độ hoặc dừng lại để bảo đảm an toàn khi tránh xe đi ngược chiều. Điều này đồng nghĩa, ngay cả khi đang di chuyển đúng phần đường, tài xế vẫn có trách nhiệm chủ động phòng tránh nguy hiểm, không được cố tình gây va chạm với phương tiện khác. Đối với tình huống trong đoạn video nói trên, tài xế ô tô màu trắng có dấu hiệu vi phạm quy định về chiều lưu thông. Theo điểm d, khoản 9, điều 6 Nghị định 168/2024/NĐ-CP, hành vi điều khiển ô tô đi ngược chiều trên đường một chiều hoặc đường có biển "cấm đi ngược chiều" có thể bị phạt tiền từ 18 - 20 triệu đồng. Trường hợp hành vi vi phạm gây tai nạn giao thông, mức phạt tăng lên 20 - 22 triệu đồng, đồng thời bị trừ 10 điểm Giấy phép lái xe. Không riêng tài xế ô tô chạy ngược chiều, người lái xe taxi cũng có thể bị xử phạt ẢNH: CẮT TỪ CLIP Tuy nhiên, tài xế taxi cũng có thể phải chịu trách nhiệm nếu cơ quan chức năng xác định người này đã phát hiện xe đi ngược chiều, có đủ điều kiện giảm tốc độ hoặc dừng lại để tránh va chạm nhưng không thực hiện. Theo điểm a, khoản 10, điều 6 Nghị định 168/2024/NĐ-CP, hành vi điều khiển ô tô không quan sát, giảm tốc độ hoặc dừng lại để bảo đảm an toàn theo quy định mà gây tai nạn giao thông có thể bị phạt 20 - 22 triệu đồng, đồng thời bị trừ 10 điểm Giấy phép lái xe. Dù vậy, chỉ từ hình ảnh camera hành trình chưa đủ cơ sở kết luận tài xế taxi cố tình gây tai nạn. Việc xác định trách nhiệm của từng bên cần căn cứ vào kết quả xác minh của cơ quan chức năng, bao gồm diễn biến va chạm, tốc độ, khả năng quan sát, điều kiện tránh va chạm cũng như hệ thống biển báo, tổ chức giao thông tại khu vực xảy ra vụ việc.
A7: =RANK(J7,$J$2:$J$21) | B7: Thói quen húp cạn nước phở: Đã miệng một lúc, hại thận và tim cả đời | C7: https://voz.vn/t/thoi-quen-hup-can-nuoc-pho-da-mieng-mot-luc-hai-than-va-tim-ca-doi.1290967/ | D7: https://vov.vn/doi-song/thoi-quen-hup-can-nuoc-pho-da-mieng-mot-luc-hai-than-va-tim-ca-doi-post1343592.vov | E7: vov.vn | F7: 58 | G7: 49 | H7: 3.4 | I7: =F7*ThamSo!$B$2+G7*ThamSo!$B$3 | J7: =IFERROR(I7/POWER(H7+ThamSo!$B$5,ThamSo!$B$4),0) | K7: 20 | L7: Xoibanhmat | M7: 2026-10-22 11:38 | N7: 3 | O7: ok | P7: VOV.VN - Chỉ một bát phở có thể chứa trọn lượng muối cho cả ngày dài, khiến thói quen húp cạn nước dùng âm thầm trở thành gánh nặng lớn cho thận và tim mạch. Một bát phở nóng hổi với làn khói nghi ngút là lựa chọn quen thuộc của nhiều người để bắt đầu ngày mới. Không ít người còn có thói quen húp cạn phần nước dùng ngọt đậm để cảm nhận trọn vẹn sự tinh túy của bát phở. Tuy nhiên, ít ai ngờ rằng chính phần nước cốt thơm ngon này lại là nơi tiềm ẩn nhiều rủi ro sức khỏe nếu tiêu thụ quá thường xuyên. Theo TS Lê Thị Hương Giang, Trưởng khoa Tiết chế dinh dưỡng, Bệnh viện 19-8, nguyên nhân không nằm ở bánh phở hay từng lát thịt tươi, mà ẩn nấp ngay trong làn nước dùng đậm đà. Trung bình một bát phở chứa khoảng 400-500 ml nước dùng. Lượng nước này mang theo từ 2,5 đến 5 gram muối (tương đương 1.000-2.000 mg Natri). Trong khi đó, Tổ chức Y tế Thế giới (WHO) khuyến cáo mỗi người trưởng thành chỉ nên nạp tối đa 5 gram muối mỗi ngày. Như vậy, chỉ cần húp cạn một tô phở vào buổi sáng, bạn đã nạp gần như trọn vẹn hạn ngạch muối cho cả ngày dài. Điều nguy hiểm là vị mặn này thường bị “đánh lừa” bởi vị ngọt tự nhiên từ xương hầm cùng đủ loại gia vị nêm nếm. Người ăn mải mê thưởng thức sự hài hòa ấy mà không hề hay biết cơ thể đang phải nạp một lượng natri khổng lồ. https://vov.vn/doi-song/thoi-quen-hup-can-nuoc-pho-da-mieng-mot-luc-hai-than-va-tim-ca-doi-post1343592.vov
A8: =RANK(J8,$J$2:$J$21) | B8: Xử lý nghiêm ngân hàng không giảm lãi suất | C8: https://voz.vn/t/xu-ly-nghiem-ngan-hang-khong-giam-lai-suat.1290894/ | D8: https://tienphong.vn/trai-phieu-nong-giua-luc-lai-suat-ngan-hang-i-ach-ha-nhiet-post1887282.tpo | E8: tienphong.vn | F8: 77 | G8: 49 | H8: 6.06 | I8: =F8*ThamSo!$B$2+G8*ThamSo!$B$3 | J8: =IFERROR(I8/POWER(H8+ThamSo!$B$5,ThamSo!$B$4),0) | K8: 20 | L8: Vanguard_VietNam | M8: 2026-10-22 08:59 | N8: 4 | O8: ok | P8: Ngày 21/10, Ngân hàng Nhà nước Việt Nam ban hành Công văn số 9736 yêu cầu các ngân hàng thương mại quyết liệt thực hiện việc giảm thực chất lãi suất huy động và cho vay. Đáng chú ý, cơ quan quản lý cảnh báo sẽ xử lý nghiêm những ngân hàng không chấp hành, trong đó có biện pháp xem xét giảm hoặc giao chỉ tiêu tăng trưởng tín dụng thấp hơn. Theo chỉ đạo mới, các ngân hàng thương mại phải triển khai đồng bộ trên toàn hệ thống và tất cả các kênh bán hàng, thực hiện nghiêm yêu cầu giảm lãi suất của Thống đốc Ngân hàng Nhà nước tại cuộc họp ngày 19/10 và Công văn số 9608 ngày 18/10. Ngân hàng Nhà nước thúc giục các ngân hàng giảm lãi suất trên mọi kênh. Ảnh: NY. Cụ thể, trong những tháng cuối năm 2026, các ngân hàng phải giảm tối thiểu 0,5%/năm đối với lãi suất tiền gửi bình quân của các giao dịch phát sinh mới có kỳ hạn từ 6 tháng trở lên. Mức giảm được so sánh với lãi suất của chính ngân hàng đó trong kỳ báo cáo từ ngày 11/1-20/10. Để giám sát việc thực hiện, Ngân hàng Nhà nước sẽ theo dõi số liệu lãi suất bình quân của các giao dịch phát sinh mới tại ngân hàng trong những tháng cuối năm thông qua hệ thống báo cáo thống kê. Trường hợp ngân hàng thương mại không thực hiện chỉ đạo, Ngân hàng Nhà nước sẽ có biện pháp xử lý nghiêm. https://tienphong.vn/xu-ly-nghiem-ngan-hang-khong-giam-lai-suat-post1887327.tpo
A9: =RANK(J9,$J$2:$J$21) | B9: CEO PNJ: Công ty cạn tiền vì khách bán lại kim cương gấp 10 lần | C9: https://voz.vn/t/ceo-pnj-cong-ty-can-tien-vi-khach-ban-lai-kim-cuong-gap-10-lan.1290721/ | D9: https://znews.vn/tieu-diem/pnj.html | E9: znews.vn | F9: 133 | G9: 108 | H9: 24.34 | I9: =F9*ThamSo!$B$2+G9*ThamSo!$B$3 | J9: =IFERROR(I9/POWER(H9+ThamSo!$B$5,ThamSo!$B$4),0) | K9: 20 | L9: luzshop | M9: 2026-10-21 14:42 | N9: 7 | O9: ok | P9: PNJ cho biết làn sóng khách bán lại kim cương khiến doanh nghiệp cạn tiền, dự kiến nâng dự phòng lên 7.100 tỷ đồng và huy động 8.000 tỷ đồng để tái cấu trúc. Tại phiên họp ĐHĐCĐ bất thường ngày 21/10, ông Phan Quốc Công, CEO Công ty CP Vàng bạc Đá quý Phú Nhuận ( PNJ ), cho biết doanh nghiệp đã rơi vào tình trạng cạn kiệt thanh khoản sau làn sóng khách hàng bán lại kim cương bùng phát hồi tháng 7. Chỉ riêng tháng 7, giá trị sản phẩm khách hàng mang bán lại đã lên tới gần 6.000 tỷ đồng, trong khi lượng khách giao dịch mỗi ngày tăng gấp 10 lần bình thường. ​ Lỗ 258 tỷ quý II, nợ ngân hàng 3.000 tỷ đồng ​ Theo ông Công, sự cố pháp lý tại Thanh Hóa vào đầu tháng 7 đã làm dấy lên lo ngại trên thị trường. Ông gọi đây là sự kiện “thiên nga đen”, có tính chất bất ngờ và ảnh hưởng sâu rộng, làm thay đổi mạnh mẽ thị trường kim cương Việt Nam. Trước sự cố, tại ngày 30/6, PNJ vẫn có lượng tiền mặt và tiền gửi tạo thành đệm tài chính an toàn. Tuy nhiên, khi khách hàng đồng loạt bán lại sản phẩm, phần lớn tiền mặt của doanh nghiệp đã chuyển thành hàng tồn kho mua lại từ khách hàng. Trong năm 2025, giá trị khách hàng bán lại trên toàn hệ thống PNJ vào khoảng 7.000 tỷ đồng, với tỷ lệ thu đổi thông thường khoảng 30% mỗi năm trên tổng giá trị tích lũy. Tuy nhiên, làn sóng bán lại trong tháng 7 đã vượt xa mức thông thường. Áp lực càng lớn khi nhóm kim cương và trang sức kim cương chiếm tới 52% tổng hàng tồn kho của PNJ. Đến cuối quý III, tổng giá trị tích lũy từ các cam kết thu đổi kim cương và trang sức kim cương của doanh nghiệp vào khoảng 24.000 tỷ đồng. Riêng nhóm này có giá trị cam kết khoảng 21.000 tỷ tại ngày 30/9. Các cam kết thu đổi trước đây không có thời hạn. Trong bối cảnh doanh thu chưa phục hồi, PNJ cũng khó bán thanh lý lượng lớn kim cương để tạo tiền mặt. Theo lãnh đạo doanh nghiệp, việc bán số lượng lớn trong thời gian ngắn đòi hỏi mức chiết khấu sâu, trong khi thị trường có thể cần nhiều năm để hấp thụ hết lượng hàng. Để ứng phó, PNJ đã điều chỉnh chính sách thu đổi, chuyển sang thanh toán trong vòng 120 ngày đối với kim cương. Với vàng trang sức, thời gian thanh toán sau đó được rút ngắn xuống T+2 và T+7. Tuy nhiên, việc thay đổi chính sách thu đổi cũng ảnh hưởng đến sức mua và niềm tin khách hàng. Doanh thu bán lẻ giảm xuống còn chưa bằng 1/3 mức bình thường trước sự cố. Trong quý III, PNJ cắt giảm 13% chi phí bán hàng và quản lý doanh nghiệp so với cùng kỳ nhưng vẫn lỗ 258 tỷ đồng, chưa bao gồm khoản trích lập dự phòng mới. Về nghĩa vụ tài chính, dư nợ vay ngân hàng của PNJ hiện ở mức 3.000 tỷ đồng, đều là các khoản vay ngắn hạn có tài sản bảo đảm. Khoản phải trả khách hàng và đối tác theo lộ trình thanh toán 120 ngày là 125 tỷ đồng. Để giải quyết khó khăn thanh khoản tạm thời, Chủ tịch HĐQT cùng các cổ đông lớn đã cho công ty vay cá nhân tổng cộng 700 tỷ đồng, được giải ngân trong hai ngày 15/9 và 25/9. PNJ đồng thời cần duy trì khoảng 100-150 tỷ đồng mỗi tháng cho các hoạt động vận hành cơ bản. ​ Tăng dự phòng lên 7.100 tỷ, cần huy động 8.000 tỷ đồng ​ Theo phương án trình cổ đông, PNJ dự kiến tăng khoản dự phòng tổn thất kế toán từ 2.300 tỷ lên khoảng 7.100 tỷ đồng. Việc điều chỉnh gắn với thay đổi giả định về tỷ lệ khách hàng thực hiện quyền thu đổi, từ 30% lên 80%. Với riêng nhóm kim cương và trang sức kim cương có giá trị cam kết thu đổi tích lũy khoảng 21.000 tỷ đồng, nếu áp dụng tỷ lệ thực hiện 80%, giá trị thu đổi tương ứng vào khoảng 16.500 tỷ đồng theo tính toán của doanh nghiệp. Đối với sản phẩm mới, PNJ định hướng chuyển sang thu đổi theo giá thị trường thực tế tại thời điểm giao dịch, thay vì tiếp tục cam kết tỷ lệ phần trăm cố định trên hóa đơn như trước đây. Ông Công nhấn mạnh khoản dự phòng khoảng 7.000 tỷ là tác động kế toán, khác với nhu cầu tiền mặt 8.000 tỷ đồng mà doanh nghiệp đang đặt ra. Việc trích lập dự phòng không đồng nghĩa công ty phải chi ngay khoản tiền tương ứng, mà nhằm phản ánh rủi ro trên cơ sở tính toán. Để khôi phục hoạt động, PNJ trình cổ đông phương án huy động 8.000 tỷ đồng. Trong đó,…
A10: =RANK(J10,$J$2:$J$21) | B10: Australia đang xem xét hồ sơ lập hãng bay của Vietjet | C10: https://voz.vn/t/australia-dang-xem-xet-ho-so-lap-hang-bay-cua-vietjet.1290310/ | D10: https://tapchihangkhong.vn/hang-hang-khong-moi-cua-vietjet-tai-australia-co-the-bay-den-nhung-dau-d13755.html | E10: tapchihangkhong.vn | F10: 154 | G10: 200 | H10: 52.47 | I10: =F10*ThamSo!$B$2+G10*ThamSo!$B$3 | J10: =IFERROR(I10/POWER(H10+ThamSo!$B$5,ThamSo!$B$4),0) | K10: 20 | L10: Xephinhkieumy19 | M10: 2026-10-20 10:34 | N10: 8 | O10: ok | P10: Trung Kiên - 20/10/2026 - 09:32 (TCHK) - Vietjet đang được xem xét hồ sơ xin cấp phép khai thác hàng không tại Australia, với kế hoạch vận hành đội bay tối đa 10 chiếc Boeing 737 dưới tên Cherrie Air. Vietjet xin vận hành tối đa 10 máy bay Boeing 737 ở Australia​ Theo The Sydney Morning Herald , Vietjet đã nộp hồ sơ lên Cơ quan An toàn Hàng không Dân dụng Australia (CASA) để xin cấp Giấy phép Khai thác Hàng không (AOC), qua đó có thể khai thác các đường bay nội địa tại nước này. Kế hoạch được đề cập là vận hành tối đa 10 máy bay Boeing 737 trên các tuyến kết nối Sydney, Melbourne và Brisbane, dưới tên gọi Cherrie Air. Vietjet đã nộp hồ sơ lên Cơ quan An toàn Hàng không Dân dụng Australia (CASA) để xin cấp Giấy phép Khai thác Hàng không (AOC) CASA cho biết Đạo luật Hàng không Dân dụng cho phép cơ quan này đánh giá năng lực tài chính của doanh nghiệp trong quá trình xem xét hồ sơ xin cấp AOC. Theo cơ quan quản lý, việc thẩm định được thực hiện, đặc biệt đối với các đơn xin phép khai thác vận tải hàng không quy mô lớn. Việc hồ sơ đang được xem xét chưa đồng nghĩa Cherrie Air đã được cấp phép hoặc có thể bắt đầu khai thác. Để triển khai kế hoạch, hãng còn phải đáp ứng các yêu cầu quản lý và an toàn hàng không của Australia. Vietjet là một trong những hãng hàng không tư nhân đầu tiên của Việt Nam, bắt đầu hoạt động từ năm 2011. Trong quá trình phát triển, hãng tập trung mở rộng mạng bay quốc tế và xây dựng hiện diện tại một số thị trường nước ngoài, trong đó có Thái Lan và Kazakhstan. Nếu kế hoạch tại Australia được thông qua, Vietjet sẽ có thêm cơ hội tham gia thị trường nội địa của một trong những quốc gia có mạng hàng không phát triển, nhưng cũng đối mặt với yêu cầu cao về năng lực tài chính, vận hành và tuân thủ quy định sở tại. Từ đường bay quốc tế đến tham vọng khai thác nội địa​ Kế hoạch tại Australia cần được nhìn nhận trong chiến lược mở rộng hiện diện ở nước ngoài của Vietjet. Hãng không chỉ tăng tần suất trên các đường bay quốc tế hiện có mà còn tiếp tục mở những điểm đến mới, trong đó có Trung Á, Trung Âu và Australia. Theo thông tin công bố của Vietjet và chính quyền bang New South Wales, hãng dự kiến khai thác đường bay thẳng TP.HCM - Western Sydney từ tháng 1/2027, với hai chuyến khứ hồi mỗi tuần trong giai đoạn đầu. Đây là dịch vụ quốc tế, sử dụng máy bay Airbus A330, khác với kế hoạch lập hãng bay nội địa Cherrie Air đang xin phê duyệt tại Australia. Hiện Vietjet đã khai thác các đường bay kết nối TP.HCM với Sydney, Melbourne, Brisbane và Perth. Việc mở thêm đường bay đến Western Sydney sẽ giúp hãng tiếp cận một cửa ngõ hàng không mới của khu vực Sydney, đồng thời mở rộng lựa chọn cho hành khách đi lại giữa Việt Nam và Australia. Nếu được cấp phép khai thác, Cherrie Air sẽ theo đuổi một phân khúc khác với mạng bay quốc tế hiện tại của Vietjet. Các tuyến Sydney - Melbourne - Brisbane thuộc những hành lang hàng không đông khách nhất Australia, nhưng cũng là thị trường cạnh tranh với sự hiện diện của các hãng lớn như Qantas, Jetstar và Virgin Australia. Hiệu quả khai thác vì thế sẽ phụ thuộc vào việc hãng đáp ứng các điều kiện cấp phép, xây dựng mạng bay và kiểm soát chi phí vận hành. Một dấu hiệu cho thấy kế hoạch đã tiến xa hơn mức ý tưởng là máy bay Boeing 737 mang số đăng ký VH-T8A xuất hiện trong sổ đăng bạ của CASA từ tháng 9/2026, với đơn vị khai thác đăng ký tại Melbourne mang tên Cherrie Aviation. Theo Australian Aviation , đại diện Vietjet cho biết hãng đã đồng ý cho một pháp nhân tại Australia thuê chiếc máy bay này, trong khi pháp nhân đó đang tìm kiếm phê duyệt quản lý để khai thác. Kế hoạch tại Australia cần được nhìn nhận trong chiến lược mở rộng hiện diện ở nước ngoài của Vietjet. Dù vậy, đăng ký máy bay hay chuẩn bị pháp nhân không thay thế được AOC. Đây vẫn là bước phê duyệt quan trọng để doanh nghiệp có thể chính thức cung cấp dịch vụ vận tải hàng không. Hàng không Việt tăng trưởng mạnh Theo số liệu Cục Hàng không Việt Nam, tính đến ngày 22/9/2026, Việt Nam có 258 máy bay đăng ký quốc tịch Việt Nam…
A11: =RANK(J11,$J$2:$J$21) | B11: (Dịch) (Quốc tế) Tổ chức an ninh mạng cảnh báo các trang web có thể bị đóng khi PHP chuẩn bị bản vá lỗi quan trọng. | C11: https://voz.vn/t/dich-quoc-te-to-chuc-an-ninh-mang-canh-bao-cac-trang-web-co-the-bi-dong-khi-php-chuan-bi-ban-va-loi-quan-trong.1290760/ | D11: https://www.reuters.com/world/asia-pacific/eu-agency-warns-websites-may-need-be-taken-offline-php-prepares-patches-2026-10-21/ | E11: reuters.com | F11: 75 | G11: 77 | H11: 22.14 | I11: =F11*ThamSo!$B$2+G11*ThamSo!$B$3 | J11: =IFERROR(I11/POWER(H11+ThamSo!$B$5,ThamSo!$B$4),0) | K11: 20 | L11: Doores | M11: 2026-10-21 16:54 | N11: 4 | O11: ok | P11: 21 tháng 10 (Reuters) - Các nhà phát triển ngôn ngữ lập trình PHP được sử dụng rộng rãi cho biết hôm thứ Tư rằng họ sẽ phát hành các bản vá cho hai lỗ hổng nghiêm trọng, trong khi các quan chức an ninh mạng của EU cảnh báo các tổ chức không thể áp dụng các bản vá này nên tạm ngừng hoạt động các trang web bị ảnh hưởng. PHP được sử dụng rộng rãi trên internet, và trong ngày qua đã xuất hiện nhiều đồn đoán rằng các trang web sử dụng phần mềm này có thể dễ bị tấn công mạng nghiêm trọng. "PHP có mặt ở khắp mọi nơi. Nó âm thầm vận hành các trang web WordPress, Drupal, Joomla và Magento, các nền tảng lưu trữ chia sẻ, bảng điều khiển và rất nhiều phần mềm khác mà thậm chí không hề quảng cáo rằng chúng đang chạy PHP bên trong," công ty an ninh mạng Huntress cho biết trong một bài đăng trên blog. Trong bản cập nhật bảo mật, PHP cho biết cả hai lỗ hổng đều được xếp hạng 9.2 trên thang đo độ nghiêm trọng CVSS v4.0 và khuyến cáo người dùng "nâng cấp ngay khi bản phát hành có sẵn". Thông báo cho biết bản vá cho cả hai lỗ hổng dự kiến sẽ được phát hành vào lúc 14:00 GMT ngày thứ Tư. Dane Knecht, giám đốc công nghệ của công ty bảo mật web và điện toán đám mây Cloudflare (NET.N). Ông cho biết các cuộc tấn công đang xuất hiện và Cloudflare đang cập nhật các quy tắc tường lửa của mình như một biện pháp tạm thời. "Chúng tôi đang phát hiện các cuộc tấn công ban đầu và đang cập nhật các biện pháp giảm thiểu khi các phương thức tấn công mới xuất hiện. Đây chỉ là biện pháp tạm thời. Hãy vá lỗi ngay khi PHP phát hành bản cập nhật", ông nói trên X. Nhóm ứng phó khẩn cấp máy tính của Liên minh châu Âu (CERT-EU) cho biết trong một thông báo hôm thứ Ba rằng mức xếp hạng 9.2 cho thấy nguy cơ thực thi mã từ xa không cần xác thực, một loại lỗ hổng cho phép kẻ tấn công chạy mã độc hại trên các hệ thống dễ bị tổn thương mà không cần đăng nhập. CERT-EU kêu gọi các tổ chức chuẩn bị vá lỗi ngay lập tức cho các nơi bị ảnh hưởng và cho biết những tổ chức nào không thể làm như vậy nên xem xét việc tạm ngừng hoạt động các trang web bị ảnh hưởng. Trung tâm An ninh mạng Úc (ACSC) đã đưa ra hướng dẫn tương tự, kêu gọi các tổ chức xác định PHP trong hệ thống của họ, chuẩn bị áp dụng các bản vá lỗi và giám sát các ứng dụng để phát hiện các dấu hiệu hoạt động độc hại. "ACSC hiện chưa phát hiện hoạt động khai thác nào liên quan đến các lỗ hổng này", cơ quan này cho biết. Nhà cung cấp dịch vụ lưu trữ web GoDaddy cho biết các lỗ hổng này có thể cho phép kẻ tấn công thực thi mã trên các máy chủ bị ảnh hưởng thông qua internet, có khả năng dẫn đến đánh cắp dữ liệu, phá hoại trang web hoặc xâm phạm toàn bộ hệ thống. Wordfence, một plugin bảo mật bảo vệ các trang web WordPress, cho biết tất cả các trang web WordPress đều chạy trên máy chủ được cài đặt PHP. Họ cảnh báo rằng các bản cập nhật tự động sẽ không áp dụng bản vá lỗi và khuyên chủ sở hữu trang web nên tìm hiểu xem ai chịu trách nhiệm cập nhật PHP trên trang web của họ. Nhóm bảo mật của PHP cho biết chi tiết về các lỗ hổng, các phiên bản bị ảnh hưởng và các bản phát hành đã được sửa lỗi sẽ được công bố khi các bản vá được phát hành. CERT-EU và ACSC cho biết tất cả các phiên bản PHP từ PHP 5 trở lên đều có thể bị ảnh hưởng, mặc dù PHP chưa tiết lộ phiên bản nào dễ bị tổn thương. https://www.reuters.com/world/asia-pacific/eu-agency-warns-websites-may-need-be-taken-offline-php-prepares-patches-2026-10-21/
A12: =RANK(J12,$J$2:$J$21) | B12: Công ty của kỹ sư người Việt phát hiện "lỗ hổng" đe dọa 70% website toàn cầu | C12: https://voz.vn/t/cong-ty-cua-ky-su-nguoi-viet-phat-hien-lo-hong-de-doa-70-website-toan-cau.1290969/ | D12: https://dantri.com.vn/kinh-doanh/cong-ty-cua-ky-su-nguoi-viet-phat-hien-lo-hong-de-doa-70-website-toan-cau-20261022003337790.htm | E12: dantri.com.vn | F12: 40 | G12: 27 | H12: 3.35 | I12: =F12*ThamSo!$B$2+G12*ThamSo!$B$3 | J12: =IFERROR(I12/POWER(H12+ThamSo!$B$5,ThamSo!$B$4),0) | K12: 15 | L12: Doores | M12: 2026-10-22 11:41 | N12: 3 | O12: ok | P12: (Dân trí) - Một lỗ hổng ẩn trong PHP suốt nhiều năm vừa được đưa ra ánh sáng nhờ trí tuệ nhân tạo. Đứng sau phát hiện này là Calif, công ty bảo mật có trụ sở tại California (Mỹ) do kỹ sư Thái Dương điều hành.​ Ngày 21/10, những người phát triển PHP, ngôn ngữ lập trình dùng để xây dựng website, hiện vận hành khoảng 70% trang web trên toàn cầu, đã công bố một lỗ hổng bảo mật nghiêm trọng cho phép kẻ tấn công chiếm quyền kiểm soát bất kỳ máy chủ nào chạy phần mềm này. Từ đó, tin tặc có thể đánh cắp dữ liệu hoặc dùng chính website bị xâm nhập để tấn công người truy cập. Lỗ hổng được đặt tên PHP2Shell, thực chất là một nhóm vấn đề liên quan đến cách PHP quản lý bộ nhớ máy tính. Nó có thể bị khai thác theo nhiều cách khác nhau, có trường hợp chỉ mất vài giây, để chạy mã trái phép trên các máy chủ chưa được vá lỗi. Volker Dusch, kỹ sư bảo mật của tổ chức phi lợi nhuận quản lý dự án PHP, gọi đây là sự cố bảo mật nghiêm trọng nhất mà PHP đối mặt trong hơn một thập kỷ. Ông so sánh nó với Heartbleed (lỗ hổng trong thư viện mã hóa OpenSSL năm 2014, từng khiến cả thế giới phải chạy đua bảo vệ hàng trăm nghìn máy chủ). Điểm khiến giới chuyên gia lo ngại hơn cả là bối cảnh mới: Khi bản vá được công bố, tin tặc có thể phân tích những thay đổi trong mã nguồn (bộ mã lập trình gốc của phần mềm) để tìm ra cách tấn công, và trí tuệ nhân tạo (AI) làm việc này nhanh hơn bất kỳ con người nào. Một lỗ hổng ẩn trong PHP suốt nhiều năm vừa được phát hiện (Ảnh minh họa: CV). Kỹ sư Thái Dương (Dương Ngọc Thái), giám đốc điều hành Calif, cảnh báo trên The Wall Street Journal rằng chỉ cần một cá nhân bất kỳ lấy bản vá, dùng trí tuệ nhân tạo để dựng mã khai thác - đoạn chương trình lợi dụng lỗ hổng để tấn công - rồi đăng lên mạng là tình hình sẽ trở nên hỗn loạn. Một số quản trị viên cho biết họ chủ động tắt website trong khi chờ cập nhật. Trí tuệ nhân tạo tìm ra thứ con người đã bỏ qua Người trực tiếp phát hiện lỗ hổng là Ryan Austin, nhà nghiên cứu tại Calif, trong một đợt kiểm tra mã nguồn PHP vào tháng 8/2026 với sự hỗ trợ của GPT-5.6 Sol (một trong những mô hình trí tuệ nhân tạo tiên tiến nhất của OpenAI, công ty tạo ra ChatGPT). Đợt kiểm tra này do OpenAI tài trợ, nằm trong nỗ lực của các công ty trí tuệ nhân tạo nhằm giúp các dự án mã nguồn mở (phần mềm công khai mã nguồn, do cộng đồng tình nguyện phát triển) xử lý những lỗ hổng mà hệ thống AI ngày càng phát hiện ra nhiều. Điều đáng chú ý là loại lỗi này không hề mới. Theo ông Thái Dương, một nhà nghiên cứu từng chỉ ra vấn đề từ nhiều thập kỷ trước, nhưng vì bị cho là quá khó khai thác nên nó dần rơi vào quên lãng. Trí tuệ nhân tạo đã tìm được lối đi: Austin xây dựng được cách điều khiển mã đang chạy trong bộ nhớ chỉ với vài chục yêu cầu gửi tới máy chủ PHP. Trên hệ thống nhỏ, cuộc tấn công hoàn tất trong vài giây; trên hệ thống phức tạp hơn, có thể mất vài giờ. Ngày 11/8, ông Thái Dương gọi điện cho ông Dusch. Ông Dusch kể rằng phản ứng đầu tiên của ông là hoang mang, không biết phải truyền đạt chuyện này ra sao, rồi sau đó bình tĩnh lại và bắt tay vào sửa lỗi. Một nhóm làm việc không chính thức nhanh chóng hình thành giữa các nhà nghiên cứu bảo mật, kỹ sư phần mềm, nhà phân phối và các công ty bảo mật. Nhóm nghiên cứu của Wiz (công ty bảo mật điện toán đám mây, nay thuộc Google) và của OpenAI cũng độc lập tìm ra những lỗ hổng tương tự và nhanh chóng tham gia. Ami Luttwak, đồng sáng lập Wiz, nhận định PHP2Shell là lỗ hổng nghiêm trọng nhất từng được trí tuệ nhân tạo phát hiện và có lẽ quá phức tạp để con người tự tìm ra. Hai tháng giữ bí mật và một vụ rò rỉ Trong suốt quá trình khắc phục, những người liên quan giữ kín tuyệt đối sự tồn tại của lỗ hổng, vì lo sợ một tin tặc dùng trí tuệ nhân tạo có thể phát hiện và khai thác nó trước khi bản vá hoàn tất. Khối lượng công việc rất lớn: Gần 200 tập tin được chỉnh sửa, hơn 10.000 dòng mã được viết. Ngày phát hành dự kiến là 22/10. Nhưng chưa đầy hai ngày trước mốc đó, thông tin về bản vá rò rỉ trên Hacker News (diễn đàn tin tức công nghệ nổi tiếng trong gi…
A13: =RANK(J13,$J$2:$J$21) | B13: Cửa sổ 'dân số vàng': Cơ hội lịch sử không lặp lại | C13: https://voz.vn/t/cua-so-dan-so-vang-co-hoi-lich-su-khong-lap-lai.1291005/ | D13: https://thanhnien.vn/cua-so-dan-so-vang-co-hoi-lich-su-khong-lap-lai-185261010202220972.htm | E13: thanhnien.vn | F13: 31 | G13: 22 | H13: 1.15 | I13: =F13*ThamSo!$B$2+G13*ThamSo!$B$3 | J13: =IFERROR(I13/POWER(H13+ThamSo!$B$5,ThamSo!$B$4),0) | K13: 10 | L13: Thọ Gầy 4.0 | M13: 2026-10-22 13:54 | N13: 2 | O13: ok | P13: Việt Nam vẫn đang ở giai đoạn cuối của thời kỳ "dân số vàng" và cần những chính sách đột phá để biến cơ hội này thành động lực phát triển trong kỷ nguyên mới. NGUY CƠ "CHƯA GIÀU ĐÃ GIÀ"​ Theo dự báo mới nhất của Cục Thống kê, thời kỳ cơ cấu "dân số vàng" và giai đoạn dân số già sẽ đến với VN sớm hơn các dự báo trước đó. VN chính thức bước vào thời kỳ cơ cấu "dân số vàng" từ năm 2007 khi tỷ trọng dân số trẻ em (từ 0 - 14 tuổi) nhỏ hơn 30%, tỷ trọng dân số người cao tuổi (từ 65 tuổi trở lên) nhỏ hơn 15%. Trong suốt giai đoạn 2024 - 2035, dân số trong độ tuổi lao động (15 - 64 tuổi) duy trì ở mức rất cao, từ 67,4% năm 2024 xuống 66,9% năm 2035. https://thanhnien.vn/cua-so-dan-so-vang-co-hoi-lich-su-khong-lap-lai-185261010202220972.htm
... A21: =RANK(J21,$J$2:$J$21) | B21: Diện mạo Quốc học Huế sau 130 năm | C21: https://voz.vn/t/dien-mao-quoc-hoc-hue-sau-130-nam.1291029/ | D21: https://tienphong.vn/de-xuat-xep-hang-18-di-tich-o-hue-post1829157.tpo | E21: tienphong.vn | F21: 0 | G21: 1 | H21: 0.02 | I21: =F21*ThamSo!$B$2+G21*ThamSo!$B$3 | J21: =IFERROR(I21/POWER(H21+ThamSo!$B$5,ThamSo!$B$4),0) | K21: 0 | L21: Just a feeling | M21: 2026-10-22 15:01 | N21: 1 | O21: ok | P21: TPO - Trải qua 130 năm, Trường Quốc học Huế là nơi lưu giữ những nét kiến trúc cổ kính, tạo dấu ấn giáo dục và lịch sử đặc biệt. Ngôi trường hiện được chỉnh trang, nâng cấp cơ sở vật chất trước ngày kỷ niệm thành lập. Thành lập ngày 23/10/1896 dưới triều vua Thành Thái, Trường Quốc học Huế là một trong những ngôi trường trung học lâu đời nhất Việt Nam. Nằm bên sông Hương, ngôi trường mang dấu ấn kiến trúc cổ kính , đồng thời là nơi đào tạo nhiều thế hệ học sinh tài năng cho đất nước. Những ngày này, trường được chỉnh trang để chuẩn bị kỷ niệm 130 năm thành lập. Trường mang tên ban đầu là “Pháp tự Quốc học Trường môn”, từng đổi thành Collège Quốc học, Lycée Khải Định trước khi trở lại tên Quốc học như ngày nay. Đáng chú ý, năm 2020, địa điểm trường được xếp vào hệ thống Di tích Quốc gia Đặc biệt về Chủ tịch Hồ Chí Minh tại Huế. Tấm biển "Pháp tự Quốc học Trường môn" ghi tên trường vẫn còn lưu giữ tại nhà truyền thống của trường cho tới ngày nay. Từ những dãy nhà ban đầu được cải tạo từ trại lính thủy quân, năm 1915, trường được xây dựng lại bằng gạch, vôi vữa, mái ngói theo phong cách kiến trúc phương Tây. Qua hơn một thế kỷ, những khối nhà cổ, cửa sổ và mái ngói đặc trưng tạo nên diện mạo riêng cho Quốc học Huế, lưu giữ dấu ấn lịch sử trong không gian giáo dục hiện đại. Giữa khuôn viên trường là tượng đồng Nguyễn Tất Thành, được xây dựng năm 1990 nhân kỷ niệm 100 năm ngày sinh Chủ tịch Hồ Chí Minh. Niên khóa 1908 - 1909, Người từng theo học tại đây, tham gia các hoạt động yêu nước trước khi rời Huế, tiếp tục hành trình tìm đường cứu nước. Tượng đài trở thành điểm nhấn lịch sử đặc biệt trong không gian học đường. Quốc học Huế là ngôi trường gắn với tên tuổi nhiều cựu học sinh tiêu biểu, trong đó có Chủ tịch Hồ Chí Minh, các Tổng Bí thư Trần Phú, Hà Huy Tập, Lê Duẩn và Đại tướng Võ Nguyên Giáp... Những dấu ấn ấy được lưu giữ tại nhà truyền thống, góp phần kể lại hành trình hình thành, phát triển của ngôi trường và truyền thống bồi dưỡng nhân tài qua nhiều thế hệ. Nhà truyền thống còn là nơi lưu giữ hình ảnh, tư liệu về lịch sử nhà trường cùng những thế hệ học sinh đã trưởng thành từ mái trường Quốc học. Ngôi nhà cũng là một trong những hạng mục được cải tạo trong dự án nâng cấp trường vừa triển khai, nhằm bảo tồn giá trị truyền thống, hoàn thiện không gian trưng bày và phục vụ hoạt động giáo dục lịch sử cho học sinh. Cổng trường Quốc học Huế hơn 100 năm trước. Ảnh tư liệu Một góc nhà truyền thống của trường còn lưu giữ quả chuông treo trên cổng trường, cùng tấm biển "Pháp tự Quốc học Trường môn". Bình phong long mã phía trước trường có gắn tấm bia đá ghi năm tháng thành lập trường. Các dãy phòng học, khối chức năng được kết nối bằng hệ thống hành lang có mái che bê tông, tạo lối đi thuận tiện giữa những khu vực trong trường. Bên cạnh các công trình mang dấu ấn kiến trúc đầu thế kỷ XX, những hạng mục phục vụ nhu cầu học tập , sinh hoạt hiện nay góp phần tạo nên diện mạo đan xen giữa không gian di sản và cơ sở giáo dục hiện đại. Chuẩn bị cho lễ kỷ niệm 130 năm thành lập, UBND TP. Huế đã phê duyệt dự án cải tạo, nâng cấp Trường THPT Chuyên Quốc học Huế có tổng mức đầu tư gần 16,3 tỷ đồng, khởi công tháng 9/2025. Các hạng mục gồm nhà hội trường hai tầng, nhà truyền thống và lưu niệm, nhà khách cùng hệ thống âm thanh, ánh sáng. Nhà thầu hiện hoàn tất những phần việc cuối cùng để phục vụ lễ kỷ niệm. Cùng với các công trình chính, dự án còn chỉnh trang đường nội bộ, bồn hoa, thảm cỏ, hệ thống chiếu sáng sân vườn; cải tạo nhà mỹ thuật, phòng âm nhạc, phòng sinh hoạt chuyên môn, khán đài sân vận động và nhà thi đấu thể thao. Việc hoàn thiện cơ sở vật chất hướng tới phục vụ lễ kỷ niệm 130 năm, đồng thời đáp ứng tốt hơn nhu cầu dạy và học của nhà trường. https://tienphong.vn/dien-mao-quoc-hoc-hue-sau-130-nam-post1886982.tpo

Sheet Top comments
A1: Hang thread | B1: Tieu de thread | C1: Link bai bao | D1: Hang comment | E1: Ung | F1: Tac gia | G1: Post # | H1: Link comment | I1: Thoi gian | J1: Noi dung comment
A2: 1 | B2: Đề xuất người dưới 18 tuổi được hiến tạng khi có nguyện vọng và được đồng ý | C2: https://tuoitre.vn/de-xuat-nguoi-duoi-18-tuoi-duoc-hien-tang-khi-co-nguyen-vong-va-duoc-dong-y-100261021092718637.htm | D2: 1 | E2: 3 | F2: m0use00 | G2: 2 | H2: https://voz.vn/p/44092896/ | I2: 2026-10-22 05:52 | J2: Hiện tại có một số thông tin chưa được kiểm chứng về phiếu lấy ý kiến trẻ em gì đó. Mong các bậc phụ huynh lưu ý cho con em trong nhà, tránh bị kẻ xấu lợi dụng
A3: 1 | B3: Đề xuất người dưới 18 tuổi được hiến tạng khi có nguyện vọng và được đồng ý | C3: https://tuoitre.vn/de-xuat-nguoi-duoi-18-tuoi-duoc-hien-tang-khi-co-nguyen-vong-va-duoc-dong-y-100261021092718637.htm | D3: 2 | E3: 3 | F3: Peanut1606 | G3: 3 | H3: https://voz.vn/p/44092900/ | I3: 2026-10-22 05:53 | J3: Bao giờ cho bọn 14 tuổi chịu trách nghiệm hình sự như trên 18 tuổi rồi nói chuyện
A4: 1 | B4: Đề xuất người dưới 18 tuổi được hiến tạng khi có nguyện vọng và được đồng ý | C4: https://tuoitre.vn/de-xuat-nguoi-duoi-18-tuoi-duoc-hien-tang-khi-co-nguyen-vong-va-duoc-dong-y-100261021092718637.htm | D4: 3 | E4: 3 | F4: No Mercy | G4: 4 | H4: https://voz.vn/p/44092901/ | I4: 2026-10-22 05:53 | J4: Sau khi đọc hết 4 câu hỏi lấy ý kiến trẻ em thì t rút ra 1 kết luận như sau: Hãy ráng kiếm 1 đứa con nuôi có đặc điểm sinh học càng giống mình càng tốt. Đến khi nó đủ 18 tuổi thì đá đít nó ra khỏi nhà, kiếm đứa khác. Cứ như vậy thì sẽ có nguồn tạng dự phòng bất trắc của bản thân tới cuối đời.
A5: 1 | B5: Đề xuất người dưới 18 tuổi được hiến tạng khi có nguyện vọng và được đồng ý | C5: https://tuoitre.vn/de-xuat-nguoi-duoi-18-tuoi-duoc-hien-tang-khi-co-nguyen-vong-va-duoc-dong-y-100261021092718637.htm | D5: 4 | E5: 3 | F5: cttt | G5: 5 | H5: https://voz.vn/p/44092924/ | I5: 2026-10-22 06:05 | J5: Thực tế là anh rất ngu luật. TNHS đéo phải là trên 18 tuổi mà là trên 14 tuổi rồi. Tuy nhiên, chỉ là mức độ xử lý sẽ được giảm nhẹ khi dưới 18 tuổi. Như case kinh điển là thằng luyện. Nó vẫn chịu trách nhiệm, vẫn phải đi tù nhưng ko bị án chữ thôi. Còn vẫn án số, nó cũng bị max án số Theo Điều 12 Bộ luật Hình sự 2015 (sửa đổi, bổ sung 2017), độ tuổi chịu trách nhiệm hình sự tại Việt Nam được quy định gồm 3 mốc: người từ đủ 16 tuổi trở lên chịu trách nhiệm về mọi tội phạm; người từ đủ 14 đến dưới 16 tuổi chỉ chịu trách nhiệm về một số tội rất nghiêm trọng hoặc đặc biệt nghiêm trọng; người dưới 14 tuổi không phải chịu trách nhiệm hình sự
A6: 1 | B6: Đề xuất người dưới 18 tuổi được hiến tạng khi có nguyện vọng và được đồng ý | C6: https://tuoitre.vn/de-xuat-nguoi-duoi-18-tuoi-duoc-hien-tang-khi-co-nguyen-vong-va-duoc-dong-y-100261021092718637.htm | D6: 5 | E6: 3 | F6: cttt | G6: 6 | H6: https://voz.vn/p/44092939/ | I6: 2026-10-22 06:10 | J6: PHẢN ĐỐI cái luật này. Và thằng nào nghĩ ra "đề xuất" thì bắn bỏ luôn
A7: 1 | B7: Đề xuất người dưới 18 tuổi được hiến tạng khi có nguyện vọng và được đồng ý | C7: https://tuoitre.vn/de-xuat-nguoi-duoi-18-tuoi-duoc-hien-tang-khi-co-nguyen-vong-va-duoc-dong-y-100261021092718637.htm | D7: 6 | E7: 3 | F7: Peanut1606 | G7: 7 | H7: https://voz.vn/p/44092946/ | I7: 2026-10-22 06:14 | J7: còn anh là thằng đại ngu . Thế thằng 14 tuổi được làm những việc như thằng trên 18 tuổi không ?
A8: 1 | B8: Đề xuất người dưới 18 tuổi được hiến tạng khi có nguyện vọng và được đồng ý | C8: https://tuoitre.vn/de-xuat-nguoi-duoi-18-tuoi-duoc-hien-tang-khi-co-nguyen-vong-va-duoc-dong-y-100261021092718637.htm | D8: 7 | E8: 3 | F8: liberia2010 | G8: 9 | H8: https://voz.vn/p/44092989/ | I8: 2026-10-22 06:29 | J8: Đề xuất con cháu bò ủng hộ 100% để làm lốp dự phòng cho con cháu IQ cow.
A9: 1 | B9: Đề xuất người dưới 18 tuổi được hiến tạng khi có nguyện vọng và được đồng ý | C9: https://tuoitre.vn/de-xuat-nguoi-duoi-18-tuoi-duoc-hien-tang-khi-co-nguyen-vong-va-duoc-dong-y-100261021092718637.htm | D9: 8 | E9: 3 | F9: xChabge | G9: 10 | H9: https://voz.vn/p/44093008/ | I9: 2026-10-22 06:34 | J9: Bên thread đang ầm lên vụ cho trẻ em điền form lấy ý kiến việc hiến tạng, khuyến khích tự điền không có ai can thiệp https://www.threads.com/share/BAUg_ztRt2/
A10: 1 | B10: Đề xuất người dưới 18 tuổi được hiến tạng khi có nguyện vọng và được đồng ý | C10: https://tuoitre.vn/de-xuat-nguoi-duoi-18-tuoi-duoc-hien-tang-khi-co-nguyen-vong-va-duoc-dong-y-100261021092718637.htm | D10: 9 | E10: 3 | F10: Chihiro Onitsuka | G10: 11 | H10: https://voz.vn/p/44093028/ | I10: 2026-10-22 06:38 | J10: chịu trách nghiệm hình sự như trên 18 tuổi bố ơi người ta nói chịu tương đương chứ có nói không chịu đâu bố
A11: 1 | B11: Đề xuất người dưới 18 tuổi được hiến tạng khi có nguyện vọng và được đồng ý | C11: https://tuoitre.vn/de-xuat-nguoi-duoi-18-tuoi-duoc-hien-tang-khi-co-nguyen-vong-va-duoc-dong-y-100261021092718637.htm | D11: 10 | E11: 3 | F11: chelsea.no1.hp | G11: 12 | H11: https://voz.vn/p/44093040/ | I11: 2026-10-22 06:44 | J11: Có nguồn tạng free tươi rói khg bệnh tật cho các ngài
A12: 1 | B12: Đề xuất người dưới 18 tuổi được hiến tạng khi có nguyện vọng và được đồng ý | C12: https://tuoitre.vn/de-xuat-nguoi-duoi-18-tuoi-duoc-hien-tang-khi-co-nguyen-vong-va-duoc-dong-y-100261021092718637.htm | D12: 11 | E12: 3 | F12: DMTTCM | G12: 13 | H12: https://voz.vn/p/44093053/ | I12: 2026-10-22 06:48 | J12: Thằng đề xuất mà ở các nước tư bổn là đi tù mọt gông rồi
A13: 1 | B13: Đề xuất người dưới 18 tuổi được hiến tạng khi có nguyện vọng và được đồng ý | C13: https://tuoitre.vn/de-xuat-nguoi-duoi-18-tuoi-duoc-hien-tang-khi-co-nguyen-vong-va-duoc-dong-y-100261021092718637.htm | D13: 12 | E13: 3 | F13: 章若楠 -Zhāng Ruò Nán | G13: 15 | H13: https://voz.vn/p/44093100/ | I13: 2026-10-22 06:56 | J13: +1 lý do nằm ngửa thẳng cẳng hai chân nhé. dưới 18 ăn ngủ học hành còn chưa xong, biết clj mà hiến.
... A277: 19 | B277: Hà Nội vào mùa kiến ba khoang, cảnh báo sai lầm khiến da tổn thương nặng | C277: https://dantri.com.vn/suc-khoe/ha-noi-vao-mua-kien-ba-khoang-canh-bao-sai-lam-khien-da-ton-thuong-nang-20261022091909262.htm | D277: 1 | E277: 1 | F277: NamLong0201 | G277: 3 | H277: https://voz.vn/p/44099803/ | I277: 2026-10-22 14:56 | J277: @Kiến Ba Khoan͏g

Sheet Bang ngang
A1: Hang | B1: Tieu de | C1: Link bai bao | D1: Link thread | E1: Replies | F1: Tong Ung | G1: Top 1 | H1: Top 2 | I1: Top 3 | J1: Top 4 | K1: Top 5 | L1: Top 6 | M1: Top 7 | N1: Top 8 | O1: Top 9 | P1: Top 10 | Q1: Top 11 | R1: Top 12 | S1: Top 13 | T1: Top 14 | U1: Top 15 | V1: Top 16 | W1: Top 17 | X1: Top 18 | Y1: Top 19 | Z1: Top 20
A2: 1 | B2: Đề xuất người dưới 18 tuổi được hiến tạng khi có nguyện vọng và được đồng ý | C2: https://tuoitre.vn/de-xuat-nguoi-duoi-18-tuoi-duoc-hien-tang-khi-co-nguyen-vong-va-duoc-dong-y-100261021092718637.htm | D2: https://voz.vn/t/de-xuat-nguoi-duoi-18-tuoi-duoc-hien-tang-khi-co-nguyen-vong-va-duoc-dong-y.1290864/ | E2: 383 | F2: 620 | G2: [3 Ung] @m0use00: Hiện tại có một số thông tin chưa được kiểm chứng về phiếu lấy ý kiến trẻ em gì đó. Mong các bậc phụ huynh lưu ý cho con em trong nhà, tránh bị kẻ xấu lợi dụng | H2: [3 Ung] @Peanut1606: Bao giờ cho bọn 14 tuổi chịu trách nghiệm hình sự như trên 18 tuổi rồi nói chuyện | I2: [3 Ung] @No Mercy: Sau khi đọc hết 4 câu hỏi lấy ý kiến trẻ em thì t rút ra 1 kết luận như sau: Hãy ráng kiếm 1 đứa con nuôi có đặc điểm sinh học càng giống mình càng tốt. Đến khi nó đủ 18 tuổi thì đá đít nó ra khỏi nhà, kiếm đứa khác. Cứ như vậy thì sẽ có nguồn tạng dự phòng bất trắc của bản thân tới cuối đời. | J2: [3 Ung] @cttt: Thực tế là anh rất ngu luật. TNHS đéo phải là trên 18 tuổi mà là trên 14 tuổi rồi. Tuy nhiên, chỉ là mức độ xử lý sẽ được giảm nhẹ khi dưới 18 tuổi. Như case kinh điển là thằng luyện. Nó vẫn chịu trách nhiệm, vẫn phải đi tù nhưng ko bị án chữ thôi. Còn vẫn án số, nó cũng bị max án số Theo Điều 12 Bộ luật Hình sự 2015 (sửa đổi, bổ sung 2017), độ tuổi chịu trách nhiệm hình sự tại Việt Nam được quy định gồm 3 mốc: người từ đủ 16 tuổi trở lên chịu trách nhiệm về mọi tội phạm; người từ đủ 14 đến dưới 16 tuổi chỉ chịu trách nhiệm về một số tội rất nghiêm trọng hoặc đặc biệt nghiêm trọng; người dưới 14 tuổi không phải chịu trách nhiệm hình sự | K2: [3 Ung] @cttt: PHẢN ĐỐI cái luật này. Và thằng nào nghĩ ra "đề xuất" thì bắn bỏ luôn | L2: [3 Ung] @Peanut1606: còn anh là thằng đại ngu . Thế thằng 14 tuổi được làm những việc như thằng trên 18 tuổi không ? | M2: [3 Ung] @liberia2010: Đề xuất con cháu bò ủng hộ 100% để làm lốp dự phòng cho con cháu IQ cow. | N2: [3 Ung] @xChabge: Bên thread đang ầm lên vụ cho trẻ em điền form lấy ý kiến việc hiến tạng, khuyến khích tự điền không có ai can thiệp https://www.threads.com/share/BAUg_ztRt2/ | O2: [3 Ung] @Chihiro Onitsuka: chịu trách nghiệm hình sự như trên 18 tuổi bố ơi người ta nói chịu tương đương chứ có nói không chịu đâu bố | P2: [3 Ung] @chelsea.no1.hp: Có nguồn tạng free tươi rói khg bệnh tật cho các ngài | Q2: [3 Ung] @DMTTCM: Thằng đề xuất mà ở các nước tư bổn là đi tù mọt gông rồi | R2: [3 Ung] @章若楠 -Zhāng Ruò Nán: +1 lý do nằm ngửa thẳng cẳng hai chân nhé. dưới 18 ăn ngủ học hành còn chưa xong, biết clj mà hiến. | S2: [3 Ung] @spideynolove: giờ matcha đề xuất gì cũng thông r, đám nghị gật k còn gì để làm nên nghĩ ra mấy trò con bò để XH chửi | T2: [3 Ung] @0P.Aokji: già thì hiến đất trẻ thì hiến sức lao động 25k/h con nít thì hiến tạng ôi chuyện gì đang xảy ra vậy | U2: [3 Ung] @luvFany: bọn này điên cmnr, dưới 18 nguyện vọng hiến tạng cdg vậy | V2: [3 Ung] @Tewi3k: Quá súc vật, tôi sẽ treo bot spam đơn | W2: [3 Ung] @skywave: đặc sản.... cái đéo gì xuống cũng áp chỉ tiêu, thành tích. mệt cả người triển khai lẫn thực hiện. | X2: [3 Ung] @voztechnology: Nay lên thread thấy tụi nó nói vụ này quá trời mới biết, chửi cảng ko ra cái gì luôn | Y2: [3 Ung] @[gadibo]: mẹ kiếp bọn xúc vật | Z2: [3 Ung] @Leecn2301: ĐÚng là cảm giác nó cứ giống a hai và có độ trễ như BĐS. NHờ năm nào đọc cái tin kiểu tạng này có đội nó nhận con nuôi để cho hợp phát luôn cơ. Sau tất cả thì loại người vẫn ác hơn thú
A3: 2 | B3: 'Kiến trúc sư' của web Xôi Lạc TV chính là bình luận viên Batman | C3: https://tienphong.vn/kien-truc-su-cua-web-xoi-lac-tv-chinh-la-binh-luan-vien-batman-post1887252.tpo | D3: https://voz.vn/t/kien-truc-su-cua-web-xoi-lac-tv-chinh-la-binh-luan-vien-batman.1290868/ | E3: 212 | F3: 234 | G3: [3 Ung] @William Đệ III: Mấy cái web lởm phổ thông ăn cắp này cũng có kiến trúc sư cơ à. Ngứa cái đít thế. | H3: [3 Ung] @CAPTCHA VKL: Chịu tải mấy chục nghìn đến trăm nghìn người streaming video 1 lúc thì ko còn là web lởm, phổ thông nữa đâu mai fen | I3: [3 Ung] @ConThoTrang_Yoshida: lởm á, web lúc peak lên vài chục k người xem streaming mà a nói như cái blog vườn vậy | J3: [3 Ung] @tungthanh500: Đh bkhcm hồi xưa đến đợt đăng ký môn học là tèo. Vậy mà thím còn chê lởm? | K3: [3 Ung] @Tommy Oliver: Đến trước khi sụp thì web nó vẫn mượt hơn hẳn hàng cúng cụ | L3: [3 Ung] @luongnguyen1993T: chưa nói đến cơ sở hạ tầng, video bắt bno thì bảng phòng họp lên phương án về tiếp cận, chăm sóc khách hàng, insight khách hàng, thị trường còn chuyên nghiệp cặn kẽ hơn nhiều so với mấy ông nhà đài dựa hơi | M3: [3 Ung] @Toda Erika: Batman in Arkham ah | N3: [3 Ung] @0903403999: Công Định => Động Kinh Bố mẹ đặt tên con thế này chết dở | O3: [3 Ung] @cubota: vài chục k là thế nào hồi chung kết wc2022 phải lên đến cả triệu | P3: [3 Ung] @bangaiMrY: mấy web này mà lởm thì mấy app của thằng fpt, vtv toàn cứt hết | Q3: [3 Ung] @Kurt...Cobain: Man đần giờ đá ko có bộ đôi bat-thỏ xem nhạt vkl | R3: [3 Ung] @vandeptrai: xin infor những web theo a là không lởm nào( nếu mà do a tạo ra thì càng tốt) | S3: [3 Ung] @nhozkk97: Từ khi mấy web lậu này bị phá cũng bỏ thói quen xem bóng đá đêm, vào mấy app chính thống mỗi ông thầu một giải, gói xem thì lằng nhằng, chả muốn mua xem nữa. | T3: [3 Ung] @William Đệ III: Hệ thống không phổ thông như IoT, Stream Data, Stream P2P, điểu khiển máy từ xa với Ultra cực low latency... mới cần kiến trúc sư. Còn ba cái hàng fake này bọn sinh viên nó làm, xong thuê hạ tầng có sẵn làm cho cả lô khách hàng giống nhau. Quái gì đâu mà kiến trúc sư ngứa hết cả lông dái. | U3: [3 Ung] @tripletap: Tôi giờ chỉ xem hai lai trên zootube thôi, không xem nổi cả trận | V3: [3 Ung] @Kate Ryna Marion: xoilac batman là xoilac gốc, nhưng sau bọn nó đổi thành vebo hay 90p rồi fen. Xoilac của đám Roy là bên khác, giờ vẫn còn. | W3: [3 Ung] @TruongPhamDBK: Anh nghĩ ngắn quá, nghĩ "kiến trúc sư" chỉ là nói đến chuyện làm ra cái web thôi à? Nó thiết kế và vận hành cả 1 tổ chức, từ nhân sự đến kỹ thuật, tiếp cận khách hàng, nền tảng thanh toán, ăn chia lợi nhuận, chạy quảng cáo, như kiểu giám đốc công ty, chứ không phải thằng IT quèn đâu. | X3: [3 Ung] @William Đệ III: Vl cả kiến trúc sư. Sáng ra đã gặp mẹ thằng ngáo. | Y3: [3 Ung] @vandeptrai: bầu trời không phải hình tròn đâu a, nếu như vậy thì a chỉ là thằng thợ code, ăn và code rồi được trả lương tháng thôi so thế nào được với tụi này mà gáy ))) | Z3: [3 Ung] @WSS: Anh thật sự nghĩ chỉ "liều" mà ăn cái mỏ vàng này được tận 8 năm, trụ sở ở VN à : )) Chống lưng hơi bị mạnh. Đến lúc thì lôi ra thịt lấy thành tích thôi = )
A4: 3 | B4: Tuấn Hưng: "Nếu không thích Tuấn Hưng, xin hãy phê bình Tuấn Hưng" | C4: https://phunumoi.net.vn/tuan-hung-neu-khong-thich-tuan-hung-xin-hay-phe-binh-tuan-hung-d381885.html | D4: https://voz.vn/t/tuan-hung-neu-khong-thich-tuan-hung-xin-hay-phe-binh-tuan-hung.1290986/ | E4: 128 | F4: 97 | G4: [3 Ung] @Thầy Phán: anh tau cay tml tltv lắm rồi đấy | H4: [3 Ung] @phieuvn: phê bình xong sợ anh cắt gân | I4: [3 Ung] @DMTTCM: Thằng tiến mắt trắng ko biết có ai bảo kê đằng sau mà đi chửi đổng khắp nơi vẫn ko bị xích cổ | J4: [3 Ung] @Thầy Phán: hưng gân nói nó có chống lưng mà | K4: [3 Ung] @Ryu Kenshin: Thằng chui chạn mất gốc | L4: [3 Ung] @AAdolf: Khen cũng được, chê cũng được, đừng bơ anh Hưng là được, bơ ảnh ảnh không kiếm được tiền. | M4: [3 Ung] @okamoto001: Đời a viên mãn mẹ rồi còn quan tâm gì miệng lưỡi thiên hạ, chó sủa đổng nhỉ. Trẻ thì ăn chơi, sự nghiệp lẫy lừng, già lấy vợ có điều kiện, ăn chơi, rồi giờ sang mỹ để con cái ăn uống tp sạch, hít bầu không khí sạch, hưởng giáo dục số 1 thế giới. Bản thân vẫn có việc đi hát ra tiền. Đám ma, đám cưới, thôi nôi hay gì thì kệ mẹ ra tiền là đc, sân su quan tâm chi nữa | N4: [3 Ung] @DMTTCM: Phe tiền | O4: [3 Ung] @okamoto001: Biết người ta kiếm dược bao nhiêu mà nhục hả thím, hơn nữa có việc làm có tiền ăn tiêu chả hơn là ngồi chơi à, với nghề hát thì đi hát thôi chả nhẽ đi làm tay chân được ít tiền hơn!! Kiếm tiền chính đáng có gì mà nhục | P4: [3 Ung] @matran241091: bị tấn công mạng đến mức phải đính chính mà không nhục ?? | Q4: [3 Ung] @Thích Lòng Lợn: Nhưng công nhận stt của anh viết văn như hành kinh vậy! | R4: [3 Ung] @Quan58654: Bưng bô cho lắm rồi cuối cùng vẫn phải té sang tư bẩn hết, chỉ có loser như bọn tao là bị bỏ lại ở thiên đường | S4: [3 Ung] @okamoto001: người nổi tiếng sống nhờ fame thì chấp nhận thôi thím, có ai hoàn hảo đâu có khen có chê, mặt dày kiếm tiền hưởng htụ, không dính vào pháp luật là ok rồi | T4: [3 Ung] @haylamem: Toàn thằng gato Hưng gân vào gáy bẩn. Chứ đời Hưng sang nửa sau rồi, hát vì đam mê lại có tiền dưỡng già ở nước top1 TG. Kệ lũ ở nc TG thứ 3 gáy bẩn thôi. Giờ Hưng hơn Mạnh cái logo đại bàng rồi Mạnh chỉ biết ước | U4: [3 Ung] @ưu tửu ảnh: với tính của a hưng tao thì chờ có quốc tịch mẽo là a bay về hà nội cắt gân thằng then nong ti di ngay | V4: [3 Ung] @Siêu Chuối 2626: Viên mạn lìn gì sắp đến giỗ đầu của mẹ đẻ mà còn không dám về VN để làm giỗ cho mẹ | W4: [3 Ung] @Love_Condom: Khả năng có acc. ở đây Muốn dc nhập tịch chắc a phải điên cuồng hơn nữa mới dc | X4: [3 Ung] @Tsuburaya Mitsuhiko: thấy đồn có súng dài chống lưng mới mạnh mồm thế. mà đù má bọn súng dài giờ khác đéo gì kiêu binh hãn tướng đâu: Trung, Tuấn, Can, Kiền tứ đại thiên vương.... gì chứ vụ này tôi ủng hộ bác 3 cửa mạnh tay chơi chết mẹ bọn súng dài mất dạy đi | Y4: [3 Ung] @vienngocden5: Đèo mẹ, tôi đéo quen biết gì hưng gân, cũng đéo phải fan, nhưng đọc cái còm ếch ngồi đáy giếng này ngứa cả đít. Hắn sang đéo phải để hát kiếm tiền, có nhiều lí do. Chứ tiền ở vn hắn thiếu đéo gì mà phải đi. Dù có sang mẽo thì hắn cũng vẫn đang lao động, bằng sức của hắn, ăn cắp ăn trộm của ai mà nhục ? Cái cộng đồng mạng fb nhà anh khác đéo gì bầy chó đàn, chỉ đâu cắn đấy, có tư duy là thiểu số, còn lại thì bị xỏ mũi dắt đi như bò, có cái giá trị đéo gì đâu mà nhục. Hắn cũng ở mẽo rồi, đính chính là để giữ fame, tránh bị ignore thôi, anh làm như cái cộng đồng của anh sứt được bát cơm của hắn ấy mà sợ tới mức phải đính chính. Các anh có thể chê hưng gân nhạc như lol, nghiệp ngập, bong bánh, tư cách sống-đạo đức như lol, đỏ fake... nhưng cũng buộc phải nhìn nhận là hắn đã có 1 cuộc đời, và những trải nghiệm phong phú và thành công hơn số đông rồi. Ca sĩ nổi tiếng, c… | Z4: [3 Ung] @matran241091: tôi éo bảo sang Tây là nhục để không bị mất số fame còn lại thì nó tốt nhất là ở ẩn, chứ đi hát đến độ bị tấn công mạng, trang cá nhân thì khóa bình luận , mất mẹ danh tiếng đã xây thời gian qua thì đúng là đi vào lòng đất ca sĩ sống vì fame, mất fame mà không nhục thì tôi không biết the gọi là gì nữa
